<!DOCTYPE html>
<html lang="en">

<head>
  <meta charset="UTF-8">
  <meta http-equiv="X-UA-Compatible" content="IE=edge">
  <meta name="viewport" content="width=device-width, initial-scale=1.0">
  <title>Document</title>
</head>

<body>

  <!--
    [ 기본 Promise 사용법 ]
    - 비동기로 동작되는 구문을 new Promise를 통해 반환되는 인스턴스 객체에 담아 보낸다.
    - Promise 객체에서는 then, catch 메서드 호출 가능 (동기적으로 실행)
      - Promise가 실행이 끝난 후 then이 실행된다.
      - Promise 객체 반환 시 실행이 잘 되면 then 오류가 발생하면 catch

    - 비동기 발생 대표 사례: 외부 데이터를 불러올 때 발생
    - ES6에서는 fetch라는 메서드가 기본적으로 Promise 객체를 내장하여 데이터를 반환해준다.
  -->

  <script>

    // Promise 객체를 반환하는 함수 필요
    function delay(time, cond) {

      // then, catch 메서드를 무조건 호출
      return new Promise((resolve, reject) => {

        // 동기화 발생 구문을 Promise에 넣는다.
        setTimeout(() => {
          cond ? resolve('success') : reject('fail');
        }, time);

      })
    }

    /*
      delay 함수가 Promise 객체를 반환하기 때문에 then, catch 문을 사용하여
      원하는 코드를 동기적으로 호출이 가능하다.

      아래의 then, catch 문은 해당 함수의 인수로 다시 callback 함수를 넣어야 하기 때문에 가독성이 떨어진다.
      - 문제점 개선: async await 문 활용
    */

    delay(2000, false)
      .then((res) => {
        console.log(res);
        console.log('end');
      })
      .catch((err) => {
        console.log(err);
        console.log('end');
      });

    /*
      [ async await 문 ]
      - 활용 전제 조건
        - Promise 객체를 반환하는 함수가 있어야 한다.
        - 해당 함수를 wrapping 할 함수가 필요

      - async await를 활용하면 간결하게 동기화 처리가 가능하나 catch문 활용이 불가능
        -> try catch 문으로 강제 예외처리 필요
    */

    // Promise 객체를 반환하는 함수에 await 를 사용하면 그 이후 실행되는 코드는 동기화
    async function wrapper() {
      try {

        const result = await delay(2000, false);
        console.log(result);
        console.log('end');

      } catch (err) {
        console.log(err);
      }
    }
    wrapper();

  </script>
</body>

</html>